<?xml version='1.0'?>
<sdf version="1.6">
  <model name="explorer_r2_sensor_config_1">
    <pose>0 0 0.398 0 0 0</pose>
    <link name="base_link">
      <inertial>
        <pose>0.002225 0.033355 0.022792 0 -0 0</pose>
        <mass>111.0015</mass>
        <inertia>
          <ixx>4.49753</ixx>
          <ixy>0.00199937</ixy>
          <ixz>-0.00152659</ixz>
          <iyy>2.46329</iyy>
          <iyz>-0.424901</iyz>
          <izz>5.57714</izz>
        </inertia>
      </inertial>
      <collision name="base_link_collision">
          <pose>0.25 0 0.0480 0 0 0</pose>
          <geometry>
            <box><size>0.6 0.55 0.428</size></box>
          </geometry>
      </collision>
      <collision name="base_link_fixed_joint_lump__sensor_payload_link_collision_1">
          <pose>0.38 0 0.4 0 0 0</pose>
          <geometry>
              <box>
                  <size>0.28 0.28 0.4</size>
              </box>
          </geometry>
      </collision>
      <visual name="connection_visual">
        <pose>0 0 0 0 1.5707 0</pose>
        <geometry>
          <cylinder>
            <length>0.5</length>
            <radius>0.05</radius>
          </cylinder>
        </geometry>
      </visual>
      <visual name="base_link_visual">
        <pose>0.180 0 .24 0 0 -1.5707963267948966</pose>
          <geometry>
              <mesh>
                  <uri>meshes/r2.dae</uri>
                  <submesh>
                      <name>BodyFront</name>
                      <center>true</center>
                  </submesh>
              </mesh>
          </geometry>
          <material>
              <diffuse>1.0 1.0 1.0</diffuse>
              <specular>1.0 1.0 1.0</specular>
              <pbr>
                  <metal>
                    <albedo_map>materials/textures/R2_Albedo.jpg</albedo_map>
                      <metalness_map>materials/textures/R2_Metalness.jpg</metalness_map>
                      <roughness_map>materials/textures/R2_Roughness.jpg</roughness_map>
                  </metal>
              </pbr>
              <!-- fallback to script if no PBR support-->
              <script>
                  <uri>materials/scripts/</uri>
                  <uri>materials/textures/</uri>
                  <name>UrbanTile/R2_Diffuse</name>
              </script>
          </material>
      </visual>

      <sensor name="imu_sensor" type="imu">
                <always_on>1</always_on>
                <update_rate>250</update_rate>
                <topic>imu</topic>
                <gz_frame_id>imu_link</gz_frame_id>
                <imu>
                    <enable_orientation>0</enable_orientation>
                    <angular_velocity>
                        <x>
                            <noise type="gaussian">
                                <mean>0</mean>
                                <stddev>0.009</stddev>
                                <bias_mean>0.00075</bias_mean>
                                <bias_stddev>0.005</bias_stddev>
                                <dynamic_bias_stddev>0.00002</dynamic_bias_stddev>
                                <dynamic_bias_correlation_time>400.0</dynamic_bias_correlation_time>
                                <precision>0.00025</precision>
                            </noise>
                        </x>
                        <y>
                            <noise type="gaussian">
                                <mean>0</mean>
                                <stddev>0.009</stddev>
                                <bias_mean>0.00075</bias_mean>
                                <bias_stddev>0.005</bias_stddev>
                                <dynamic_bias_stddev>0.00002</dynamic_bias_stddev>
                                <dynamic_bias_correlation_time>400.0</dynamic_bias_correlation_time>
                                <precision>0.00025</precision>
                            </noise>
                        </y>
                        <z>
                            <noise type="gaussian">
                                <mean>0</mean>
                                <stddev>0.009</stddev>
                                <bias_mean>0.00075</bias_mean>
                                <bias_stddev>0.005</bias_stddev>
                                <dynamic_bias_stddev>0.00002</dynamic_bias_stddev>
                                <dynamic_bias_correlation_time>400.0</dynamic_bias_correlation_time>
                                <precision>0.00025</precision>
                            </noise>
                        </z>
                    </angular_velocity>
                    <linear_acceleration>
                        <x>
                            <noise type="gaussian">
                                <mean>0</mean>
                                <stddev>0.021</stddev>
                                <bias_mean>0.05</bias_mean>
                                <bias_stddev>0.0075</bias_stddev>
                                <dynamic_bias_stddev>0.000375</dynamic_bias_stddev>
                                <dynamic_bias_correlation_time>175.0</dynamic_bias_correlation_time>
                                <precision>0.005</precision>
                            </noise>
                        </x>
                        <y>
                            <noise type="gaussian">
                                <mean>0</mean>
                                <stddev>0.021</stddev>
                                <bias_mean>0.05</bias_mean>
                                <bias_stddev>0.0075</bias_stddev>
                                <dynamic_bias_stddev>0.000375</dynamic_bias_stddev>
                                <dynamic_bias_correlation_time>175.0</dynamic_bias_correlation_time>
                                <precision>0.005</precision>
                            </noise>
                        </y>
                        <z>
                            <noise type="gaussian">
                                <mean>0</mean>
                                <stddev>0.021</stddev>
                                <bias_mean>0.05</bias_mean>
                                <bias_stddev>0.0075</bias_stddev>
                                <dynamic_bias_stddev>0.000375</dynamic_bias_stddev>
                                <dynamic_bias_correlation_time>175.0</dynamic_bias_correlation_time>
                                <precision>0.005</precision>
                            </noise>
                        </z>
                    </linear_acceleration>
                </imu>
            </sensor>
      <sensor name="navsat_sensor" type="navsat">
        <always_on>1</always_on>
        <update_rate>10</update_rate>
        <topic>navsat</topic>
        <gz_frame_id>gps_link</gz_frame_id>
        <navsat>
          <position_sensing>
            <horizontal>
              <noise type="gaussian">
                <mean>0.0</mean>
                <stddev>0.5</stddev>
              </noise>
            </horizontal>
            <vertical>
              <noise type="gaussian">
                <mean>0.0</mean>
                <stddev>1.0</stddev>
              </noise>
            </vertical>
          </position_sensing>
        </navsat>
      </sensor>
      
      <!-- ═══════════════════════════════════════════════════════
     Sensor: LaserScan 2D (plano horizontal, tipo Hokuyo/SICK)
     Pose respecto a base_link: adelante y a media altura
     ═══════════════════════════════════════════════════════ -->
      <sensor name="laser_scan_2d" type="gpu_lidar">
        <pose>0.37 0 0.50 0 0 0</pose>   <!-- ajusta x/z según tu robot -->
        <always_on>1</always_on>
        <update_rate>20</update_rate>
        <topic>scan</topic>
        <gz_frame_id>laser_scan_link</gz_frame_id>
        <ray>
          <scan>
            <horizontal>
              <samples>720</samples>
              <resolution>1</resolution>
              <min_angle>-3.14159265</min_angle>
              <max_angle> 3.14159265</max_angle>
            </horizontal>
            <vertical>
              <samples>1</samples>        <!-- ← CLAVE: 1 solo plano = 2D -->
              <resolution>1</resolution>
              <min_angle>0.0</min_angle>
              <max_angle>0.0</max_angle>
            </vertical>
          </scan>
          <range>
            <min>0.20</min>
            <max>30.0</max>
          </range>
          <noise>
            <type>gaussian</type>
            <mean>0.0</mean>
            <stddev>0.005</stddev>
          </noise>
        </ray>
      </sensor>
    </link>
    <link name="Rear_Rocker_Link">
      <pose>-0.047625 0 -0.0254 1.5707963267948966 0 0</pose>
      <inertial>
        <pose>-0.191018 -0.006403 -0 0 -0 0</pose>
        <mass>42.8393</mass>
        <inertia>
          <ixx>0.848992</ixx>
          <ixy>0.00301842</ixy>
          <ixz>5.21788e-06</ixz>
          <iyy>1.03049</iyy>
          <iyz>1.2171e-07</iyz>
          <izz>0.43679</izz>
        </inertia>
      </inertial>
      <collision name="Rear_Rocker_Link_collision">
        <pose>-0.2 0.072 0 0 0 0</pose>
          <geometry>
            <box><size>0.42 0.43 0.56</size></box>
          </geometry>
        </collision>
        <collision name="Rear_Rocker_Link_platform_collision1">
          <pose>-0.70 0.2855 0 -0.005 0 0</pose>
          <geometry>
            <box>
              <size>0.17 0.01 0.5</size>
            </box>
          </geometry>
        </collision>
        <collision name="Rear_Rocker_Link_platform_collision2">
          <pose>-0.35 0.2855 -0.005 -0.005 0 0</pose>
          <geometry>
            <box>
              <size>0.678 0.01 0.69</size>
            </box>
          </geometry>
        </collision>

        <visual name= "BodyRear_visual">
          <pose>-0.428 0.068 0 -1.5707963267948966 -1.5707963267948966 0</pose>
          <geometry>
            <mesh>
              <uri>meshes/r2.dae</uri>
              <submesh>
                <name>BodyRear</name>
                <center>true</center>
              </submesh>
            </mesh>
          </geometry>
          <material>
            <diffuse>1.0 1.0 1.0</diffuse>
            <specular>1.0 1.0 1.0</specular>
            <pbr>
              <metal>
                <albedo_map>materials/textures/R2_Albedo.jpg</albedo_map>
                <metalness_map>materials/textures/R2_Metalness.jpg</metalness_map>
                <roughness_map>materials/textures/R2_Roughness.jpg</roughness_map>
              </metal>
            </pbr>
            <script>
              <uri>materials/scripts/</uri>
              <uri>materials/textures/</uri>
              <name>UrbanTile/R2_Diffuse</name>
            </script>
          </material>
        </visual>
    </link>
    <joint name="Center Pivot" type="revolute">
      <child>Rear_Rocker_Link</child>
      <parent>base_link</parent>
      <axis>
        <xyz>-1 0 0</xyz>
        <limit>
          <lower>-0.5236</lower>
          <upper>0.5236</upper>
        </limit>
        <dynamics>
          <damping>10</damping>
          <friction>0.1</friction>
          <spring_reference>0.1</spring_reference>
          <spring_stiffness>100</spring_stiffness>
        </dynamics>
        <use_parent_model_frame>0</use_parent_model_frame>
      </axis>
    </joint>
    <link name="left_front_wheel_link">
      <pose>0.33421 0.363 -0.091538 -0.013747 -0 -1.5707963267948966</pose>
      <inertial>
        <pose>0.007124 -1.6e-05 4e-06 0 -0 0</pose>
        <mass>11.5398</mass>
        <inertia>
          <ixx>0.127932</ixx>
          <ixy>6.41777e-06</ixy>
          <ixz>2.40271e-06</ixz>
          <iyy>0.0695645</iyy>
          <iyz>1.35439e-09</iyz>
          <izz>0.0695643</izz>
        </inertia>
      </inertial>
      <collision name="left_front_wheel_link_collision">
        <pose>0 0 0 3.1415926535897931 1.5707963267948966 3.1415926535897931</pose>
        <geometry>
          <cylinder>
            <length>0.1125</length>
            <radius>0.31</radius>
          </cylinder>
        </geometry>
        <surface>
          <friction>
            <ode>
              <mu>0.5</mu>
              <mu2>1</mu2>
              <fdir1>0 0 1</fdir1>
              <slip1>0.0000235</slip1>
              <slip2>0</slip2>
              <max_vel>10</max_vel>
              <min_depth>0.1</min_depth>
            </ode>
          </friction>
          <contact>
            <ode>
              <kp>1e+07</kp>
              <kd>0.0001</kd>
            </ode>
          </contact>
        </surface>
      </collision>
      <visual name="left_front_wheel_link_visual">
          <geometry>
              <mesh>
                  <uri>meshes/r2.dae</uri>
                  <submesh>
                      <name>WheelFL</name>
                      <center>true</center>
                  </submesh>
              </mesh>
          </geometry>
          <material>
              <diffuse>1.0 1.0 1.0</diffuse>
              <specular>1.0 1.0 1.0</specular>
              <pbr>
                  <metal>
                      <albedo_map>materials/textures/R2_Albedo.jpg</albedo_map>
                      <metalness_map>materials/textures/R2_Metalness.jpg</metalness_map>
                      <roughness_map>materials/textures/R2_Roughness.jpg</roughness_map>
                  </metal>
              </pbr>
              <!-- fallback to script if no PBR support-->
              <script>
                  <uri>materials/scripts/</uri>
                  <uri>materials/textures/</uri>
                  <name>UrbanTile/R2_Diffuse</name>
              </script>
          </material>
      </visual>
    </link>
    <joint name="left_front_wheel" type="revolute">
      <child>left_front_wheel_link</child>
      <parent>base_link</parent>
      <axis>
        <xyz>-1 0 0</xyz>
        <limit>
          <lower>-1e+16</lower>
          <upper>1e+16</upper>
        </limit>
        <dynamics>
          <damping>10</damping>
          <friction>0.1</friction>
          <spring_reference>0</spring_reference>
          <spring_stiffness>0</spring_stiffness>
        </dynamics>
        <use_parent_model_frame>0</use_parent_model_frame>
      </axis>
    </joint>
    <link name="left_rear_wheel_link">
      <pose>-0.334625 0.363 -0.083399 -0.014389 0.000148 -1.5707963267948966</pose>
      <inertial>
        <pose>0.007124 -1.6e-05 4e-06 0 -0 0</pose>
        <mass>11.5398</mass>
        <inertia>
          <ixx>0.127932</ixx>
          <ixy>6.41777e-06</ixy>
          <ixz>2.40271e-06</ixz>
          <iyy>0.0695645</iyy>
          <iyz>1.35439e-09</iyz>
          <izz>0.0695643</izz>
        </inertia>
      </inertial>
      <collision name="left_rear_wheel_link_collision">
        <pose>0 0 0 3.1415926535897931 1.5707963267948966 3.1415926535897931</pose>
        <geometry>
          <cylinder>
            <length>0.1125</length>
            <radius>0.31</radius>
          </cylinder>
        </geometry>
        <surface>
          <friction>
            <ode>
              <mu>0.5</mu>
              <mu2>1</mu2>
              <fdir1>0 0 1</fdir1>
              <slip1>0.0000235</slip1>
              <slip2>0</slip2>
              <max_vel>10</max_vel>
              <min_depth>0.1</min_depth>
            </ode>
          </friction>
          <contact>
            <ode>
              <kp>1e+07</kp>
              <kd>0.0001</kd>
            </ode>
          </contact>
        </surface>
      </collision>
      <visual name="left_rear_wheel_link_visual">
          <geometry>
              <mesh>
                  <uri>meshes/r2.dae</uri>
                  <submesh>
                      <name>WheelBL</name>
                      <center>true</center>
                  </submesh>
              </mesh>
          </geometry>
          <material>
              <diffuse>1.0 1.0 1.0</diffuse>
              <specular>1.0 1.0 1.0</specular>
              <pbr>
                  <metal>
                      <albedo_map>materials/textures/R2_Albedo.jpg</albedo_map>
                      <metalness_map>materials/textures/R2_Metalness.jpg</metalness_map>
                      <roughness_map>materials/textures/R2_Roughness.jpg</roughness_map>
                  </metal>
              </pbr>
              <!-- fallback to script if no PBR support-->
              <script>
                  <uri>materials/scripts/</uri>
                  <uri>materials/textures/</uri>
                  <name>UrbanTile/R2_Diffuse</name>
              </script>
          </material>
      </visual>

    </link>
    <joint name="left_rear_wheel" type="revolute">
      <child>left_rear_wheel_link</child>
      <parent>Rear_Rocker_Link</parent>
      <axis>
        <xyz>-1 0 0</xyz>
        <limit>
          <lower>-1e+16</lower>
          <upper>1e+16</upper>
        </limit>
        <dynamics>
          <damping>10</damping>
          <friction>0.1</friction>
          <spring_reference>0</spring_reference>
          <spring_stiffness>0</spring_stiffness>
        </dynamics>
        <use_parent_model_frame>0</use_parent_model_frame>
      </axis>
    </joint>
    <link name="right_front_wheel_link">
      <pose>0.33421 -0.363 -0.091538 -0.013747 -0 1.5707963267948966</pose>
      <inertial>
        <pose>0.007124 -1.6e-05 4e-06 0 -0 0</pose>
        <mass>11.5398</mass>
        <inertia>
          <ixx>0.127932</ixx>
          <ixy>6.41777e-06</ixy>
          <ixz>2.40271e-06</ixz>
          <iyy>0.0695645</iyy>
          <iyz>1.35439e-09</iyz>
          <izz>0.0695643</izz>
        </inertia>
      </inertial>
      <collision name="right_front_wheel_link_collision">
        <pose>0 0 0 3.1415926535897931 1.5707963267948966 3.1415926535897931</pose>
        <geometry>
          <cylinder>
            <length>0.1125</length>
            <radius>0.31</radius>
          </cylinder>
        </geometry>
        <surface>
          <friction>
            <ode>
              <mu>0.5</mu>
              <mu2>1</mu2>
              <fdir1>0 0 1</fdir1>
              <slip1>0.0000235</slip1>
              <slip2>0</slip2>
              <max_vel>10</max_vel>
              <min_depth>0.1</min_depth>
            </ode>
          </friction>
          <contact>
            <ode>
              <kp>1e+07</kp>
              <kd>0.0001</kd>
            </ode>
          </contact>
        </surface>
      </collision>
      <visual name="right_front_wheel_link_visual">
          <geometry>
              <mesh>
                  <uri>meshes/r2.dae</uri>
                  <submesh>
                      <name>WheelFR</name>
                      <center>true</center>
                  </submesh>
              </mesh>
          </geometry>
          <material>
              <diffuse>1.0 1.0 1.0</diffuse>
              <specular>1.0 1.0 1.0</specular>
              <pbr>
                  <metal>
                      <albedo_map>materials/textures/R2_Albedo.jpg</albedo_map>
                      <metalness_map>materials/textures/R2_Metalness.jpg</metalness_map>
                      <roughness_map>materials/textures/R2_Roughness.jpg</roughness_map>
                  </metal>
              </pbr>
              <!-- fallback to script if no PBR support-->
              <script>
                  <uri>materials/scripts/</uri>
                  <uri>materials/textures/</uri>
                  <name>UrbanTile/R2_Diffuse</name>
              </script>
          </material>
      </visual>

    </link>
    <joint name="right_front_wheel" type="revolute">
      <child>right_front_wheel_link</child>
      <parent>base_link</parent>
      <axis>
        <xyz>1 0 0</xyz>
        <limit>
          <lower>-1e+16</lower>
          <upper>1e+16</upper>
        </limit>
        <dynamics>
          <damping>10</damping>
          <friction>0.1</friction>
          <spring_reference>0</spring_reference>
          <spring_stiffness>0</spring_stiffness>
        </dynamics>
        <use_parent_model_frame>0</use_parent_model_frame>
      </axis>
    </joint>
    <link name="right_rear_wheel_link">
      <pose>-0.334625 -0.363 -0.083401 -0.014389 -0.000148 1.5707963267948966</pose>
      <inertial>
        <pose>0.007124 -1.6e-05 4e-06 0 -0 0</pose>
        <mass>11.5398</mass>
        <inertia>
          <ixx>0.127932</ixx>
          <ixy>6.41777e-06</ixy>
          <ixz>2.40271e-06</ixz>
          <iyy>0.0695645</iyy>
          <iyz>1.35439e-09</iyz>
          <izz>0.0695643</izz>
        </inertia>
      </inertial>
      <collision name="right_rear_wheel_link_collision">
        <pose>0 0 0 3.1415926535897931 1.5707963267948966 3.1415926535897931</pose>
        <geometry>
          <cylinder>
            <length>0.1125</length>
            <radius>0.31</radius>
          </cylinder>
        </geometry>
        <surface>
          <friction>
            <ode>
              <mu>0.5</mu>
              <mu2>1</mu2>
              <fdir1>0 0 1</fdir1>
              <slip1>0.0000235</slip1>
              <slip2>0</slip2>
              <max_vel>10</max_vel>
              <min_depth>0.1</min_depth>
            </ode>
          </friction>
          <contact>
            <ode>
              <kp>1e+07</kp>
              <kd>0.0001</kd>
            </ode>
          </contact>
        </surface>
      </collision>
      <visual name="right_rear_wheel_link_visual">
          <geometry>
              <mesh>
                  <uri>meshes/r2.dae</uri>
                  <submesh>
                      <name>WheelBR</name>
                      <center>true</center>
                  </submesh>
              </mesh>
          </geometry>
          <material>
              <diffuse>1.0 1.0 1.0</diffuse>
              <specular>1.0 1.0 1.0</specular>
              <pbr>
                  <metal>
                      <albedo_map>materials/textures/R2_Albedo.jpg</albedo_map>
                      <metalness_map>materials/textures/R2_Metalness.jpg</metalness_map>
                      <roughness_map>materials/textures/R2_Roughness.jpg</roughness_map>
                  </metal>
              </pbr>
              <!-- fallback to script if no PBR support-->
              <script>
                  <uri>materials/scripts/</uri>
                  <uri>materials/textures/</uri>
                  <name>UrbanTile/R2_Diffuse</name>
              </script>
          </material>
      </visual>
    </link>
    <joint name="right_rear_wheel" type="revolute">
      <child>right_rear_wheel_link</child>
      <parent>Rear_Rocker_Link</parent>
      <axis>
        <xyz>1 0 0</xyz>
        <limit>
          <lower>-1e+16</lower>
          <upper>1e+16</upper>
        </limit>
        <dynamics>
          <damping>10</damping>
          <friction>0.1</friction>
          <spring_reference>0</spring_reference>
          <spring_stiffness>0</spring_stiffness>
        </dynamics>
        <use_parent_model_frame>0</use_parent_model_frame>
      </axis>
    </joint>

    <plugin filename="ignition-gazebo-diff-drive-system" name="ignition::gazebo::systems::DiffDrive">
      <left_joint>left_front_wheel</left_joint>
      <left_joint>left_rear_wheel</left_joint>
      <right_joint>right_front_wheel</right_joint>
      <right_joint>right_rear_wheel</right_joint>
      <wheel_separation>0.40</wheel_separation>
      <wheel_radius>0.1</wheel_radius>
      <topic>cmd_vel</topic>
      <odom_topic>odom</odom_topic>
      <tf_topic>tf</tf_topic>
      <frame_id>odom</frame_id>
      <child_frame_id>base_link</child_frame_id>
    </plugin>
  </model>
</sdf>